<?xml version="1.0" encoding="UTF-8"?>
<testng-results ignored="0" total="2" passed="1" failed="1" skipped="0">
  <reporter-output>
  </reporter-output>
  <suite started-at="2019-01-22T17:15:41Z" name="Default suite" finished-at="2019-01-22T17:15:51Z" duration-ms="9615">
    <groups>
    </groups>
    <test started-at="2019-01-22T17:15:41Z" name="Default test" finished-at="2019-01-22T17:15:51Z" duration-ms="9615">
      <class name="com.PackageTestNG.VerifyErrormessages">
        <test-method signature="errormessageWithGetAttribute()[pri:-2, instance:com.PackageTestNG.VerifyErrormessages@2898ac89]" started-at="2019-01-22T17:15:41Z" name="errormessageWithGetAttribute" description="check testcase using GETATTRIBUTE() to detect Error Message" finished-at="2019-01-22T17:15:41Z" duration-ms="19" status="PASS">
          <reporter-output>
          </reporter-output>
        </test-method> <!-- errormessageWithGetAttribute -->
        <test-method signature="errormessageWithGETTEXTMetod()[pri:1, instance:com.PackageTestNG.VerifyErrormessages@2898ac89]" started-at="2019-01-22T17:15:41Z" name="errormessageWithGETTEXTMetod" description="check testcase using GETTEXT() to detect Error Message" finished-at="2019-01-22T17:15:51Z" duration-ms="9549" status="FAIL">
          <exception class="java.lang.AssertionError">
            <message>
              <![CDATA[expected [true] but found [false]]]>
            </message>
            <full-stacktrace>
              <![CDATA[java.lang.AssertionError: expected [true] but found [false]
at org.testng.Assert.fail(Assert.java:96)
at org.testng.Assert.failNotEquals(Assert.java:776)
at org.testng.Assert.assertTrue(Assert.java:44)
at org.testng.Assert.assertTrue(Assert.java:54)
at com.PackageTestNG.VerifyErrormessages.errormessageWithGETTEXTMetod(VerifyErrormessages.java:33)
at java.base/jdk.internal.reflect.NativeMethodAccessorImpl.invoke0(Native Method)
at java.base/jdk.internal.reflect.NativeMethodAccessorImpl.invoke(NativeMethodAccessorImpl.java:62)
at java.base/jdk.internal.reflect.DelegatingMethodAccessorImpl.invoke(DelegatingMethodAccessorImpl.java:43)
at java.base/java.lang.reflect.Method.invoke(Method.java:564)
at org.testng.internal.MethodInvocationHelper.invokeMethod(MethodInvocationHelper.java:124)
at org.testng.internal.Invoker.invokeMethod(Invoker.java:580)
at org.testng.internal.Invoker.invokeTestMethod(Invoker.java:716)
at org.testng.internal.Invoker.invokeTestMethods(Invoker.java:988)
at org.testng.internal.TestMethodWorker.invokeTestMethods(TestMethodWorker.java:125)
at org.testng.internal.TestMethodWorker.run(TestMethodWorker.java:109)
at org.testng.TestRunner.privateRun(TestRunner.java:648)
at org.testng.TestRunner.run(TestRunner.java:505)
at org.testng.SuiteRunner.runTest(SuiteRunner.java:455)
at org.testng.SuiteRunner.runSequentially(SuiteRunner.java:450)
at org.testng.SuiteRunner.privateRun(SuiteRunner.java:415)
at org.testng.SuiteRunner.run(SuiteRunner.java:364)
at org.testng.SuiteRunnerWorker.runSuite(SuiteRunnerWorker.java:52)
at org.testng.SuiteRunnerWorker.run(SuiteRunnerWorker.java:84)
at org.testng.TestNG.runSuitesSequentially(TestNG.java:1208)
at org.testng.TestNG.runSuitesLocally(TestNG.java:1137)
at org.testng.TestNG.runSuites(TestNG.java:1049)
at org.testng.TestNG.run(TestNG.java:1017)
at org.testng.remote.AbstractRemoteTestNG.run(AbstractRemoteTestNG.java:114)
at org.testng.remote.RemoteTestNG.initAndRun(RemoteTestNG.java:251)
at org.testng.remote.RemoteTestNG.main(RemoteTestNG.java:77)
]]>
            </full-stacktrace>
          </exception> <!-- java.lang.AssertionError -->
          <reporter-output>
          </reporter-output>
        </test-method> <!-- errormessageWithGETTEXTMetod -->
      </class> <!-- com.PackageTestNG.VerifyErrormessages -->
    </test> <!-- Default test -->
  </suite> <!-- Default suite -->
</testng-results>
